<?xml version="1.0"?>
<robot name="humic" xmlns:xacro="http://ros.org/wiki/xacro">

    <!-- some parameters -->
    <xacro:property name="pi" value="3.141592654" />

    <xacro:include filename="$(find humic_description)/urdf/materials.xacro"/>

    <xacro:include filename="$(find humic_description)/urdf/humic.gazebo.xacro"/>
   
    <xacro:include filename="$(find humic_description)/urdf/humic.right_arm_transmission.xacro"/>
    <xacro:include filename="$(find humic_description)/urdf/humic.left_arm_transmission.xacro"/>
    <!-- <xacro:include filename="$(find humic_description)/urdf/humic.column_transmission.xacro"/> -->
    <!-- <xacro:include filename="$(find humic_description)/urdf/humic.right_hand_transmission.xacro"/> -->
    <!-- <xacro:include filename="$(find humic_description)/urdf/humic.left_hand_transmission.xacro"/> -->
    <!-- <xacro:include filename="$(find humic_description)/urdf/humic.head_transmission.xacro"/> -->

    <!-- base footprint -->
    <link name="base_footprint"/>

    <joint name="base_joint" type="fixed">
        <origin xyz="0 0 0.0945" rpy="0 0 0"/>
        <parent link="base_footprint"/>
        <child link="base_link"/>
    </joint>

    <!-- Mobile-Platform Body -->    
    <link name="base_link">
        <visual>
            <origin xyz="0 0 0" rpy="0 0 0"/>
            <geometry>
                <mesh filename="package://humic_description/meshes/STL/MobileBody.stl" scale="0.027 0.027 0.027"/>
            </geometry>
            <material name="white"/>
        </visual>

        <collision>
            <origin xyz="0 0 0" rpy="0 0 0"/>
            <geometry>
                <mesh filename="package://humic_description/meshes/STL/MobileBody.stl" scale="0.027 0.027 0.027"/>
            </geometry>
        </collision>

        <inertial>
            <mass value="64.126"/>
            <inertia ixx="2.43844e+08" iyy="2.46565e+09" izz="1.39943e+09" ixy="-3.45214e+06" ixz="9.87419e+06" iyz="-2.83701e+08"/>
        </inertial>
    </link>

    <!-- Mobile-Platform Wheel -->
    <!-- front left & rear right couple-->
    <!-- front right & rear left couple-->
    <joint name="rear_left_wheel_joint" type="fixed"> 
        <axis xyz="0 -1 0" />
        <origin xyz="-0.2295 0.2295 0" rpy="0 0 0"/>
        <parent link="base_link"/>
        <child link="rear_left_wheel_link"/>
    </joint>

    <link name="rear_left_wheel_link">
        <visual>
            <origin xyz="0 0 0" rpy="0 0 0"/>
            <geometry>
                <mesh
                    filename="package://humic_description/meshes/STL/wheel_rear_left.stl" scale="0.027 0.027 0.027"/>
            </geometry>
            <material name="white"/>
        </visual>

        <collision>
            <origin xyz="0 0 0" rpy="1.57 0 0"/>
            <geometry>
                <cylinder radius="0.108" length="0.0999"/>
            </geometry>
        </collision>

        <inertial>
            <mass value="1.662"/>
            <inertia ixx="7.14710e+07" iyy="1.35915e+08" izz="7.08597e+07" ixy="0.0" ixz="-6.59371e+07" iyz="0.0"/>
        </inertial>
    </link>

    <joint name="rear_right_wheel_joint" type="fixed">
        <axis xyz="0 1 0" />
        <origin xyz="-0.2295 -0.2295 0" rpy="0 0 0"/>
        <parent link="base_link"/>
        <child link="rear_right_wheel_link"/>
    </joint>

    <link name="rear_right_wheel_link">
        <visual>
            <origin xyz="0 0 0" rpy="0 0 0"/>
            <geometry>
                <mesh
                    filename="package://humic_description/meshes/STL/wheel_rear_right.stl" scale="0.027 0.027 0.027"/>
            </geometry>
            <material name="white"/>
        </visual>

        <collision>
            <origin xyz="0 0 0" rpy="1.57 0 0"/>
            <geometry>
                <cylinder radius="0.108" length="0.0999"/>
            </geometry>
        </collision>

        <inertial>
            <mass value="1.662"/>
            <inertia ixx="8.39093e+07" iyy="1.59927e+08" izz="8.34746e+07" ixy="0.0" ixz="7.74594e+07" iyz="0.0"/>
        </inertial>
    </link>

    <joint name="front_right_wheel_joint" type="fixed">
        <axis xyz="0 1 0" />
        <origin xyz="0.2295 0.2295 0" rpy="0 0 0"/>
        <parent link="base_link"/>
        <child link="front_right_wheel_link"/>
    </joint>

    <link name="front_right_wheel_link">
        <visual>
            <origin xyz="0 0 0" rpy="0 0 0"/>
            <geometry>
                <mesh
                    filename="package://humic_description/meshes/STL/wheel_front_right.stl" scale="0.027 0.027 0.027"/>
            </geometry>
            <material name="white"/>
        </visual>

        <collision>
            <origin xyz="0 0 0" rpy="1.57 0 0"/>
            <geometry>
                <cylinder radius="0.108" length="0.0999"/>
            </geometry>
        </collision>

        <inertial>
            <mass value="1.662"/>
            <inertia ixx="8.39093e+07" iyy="1.59927e+08" izz="8.34746e+07" ixy="0.0" ixz="7.74594e+07" iyz="0.0"/>
        </inertial>
    </link>

    <joint name="front_left_wheel_joint" type="fixed">
        <axis xyz="0 -1 0" />
        <origin xyz="0.2295 -0.2295 0" rpy="0 0 0"/>
        <parent link="base_link"/>
        <child link="front_left_wheel_link"/>
    </joint>

    <link name="front_left_wheel_link">
        <visual>
            <origin xyz="0 0 0" rpy="0 0 0"/>
            <geometry>
                <mesh
                    filename="package://humic_description/meshes/STL/wheel_front_left.stl" scale="0.027 0.027 0.027"/>
            </geometry>
            <material name="white"/>
        </visual>

        <collision>
            <origin xyz="0 0 0" rpy="1.57 0 0"/>
            <geometry>
                <cylinder radius="0.108" length="0.0999"/>
            </geometry>
        </collision>

        <inertial>
            <mass value="1.662"/>
            <inertia ixx="7.14710e+07" iyy="1.35915e+08" izz="7.08597e+07" ixy="0.0" ixz="-6.59371e+07" iyz="0.0"/>
        </inertial>
    </link>

    <!-- Column -->
    <joint name="base_column_joint" type="fixed">
        <origin xyz="0 0 0" rpy="0 0 0"/>
        <parent link="base_link"/>
        <child link="base_column_link"/>
    </joint>

    <link name="base_column_link">
        <visual>
            <origin xyz="0.135 0 0.2" rpy="0 0 0"/>
            <geometry>
                <mesh
                    filename="package://humic_description/meshes/STL/column_base.stl" scale="0.027 0.027 0.027"/>
            </geometry>
            <material name="white"/>
        </visual>

        <!-- <collision>
            <origin xyz="0.135 0 0.2" rpy="0 0 0"/>
            <geometry>
                <mesh
                    filename="package://humic_description/meshes/STL/column_base.stl" scale="0.027 0.027 0.027"/>
            </geometry>
        </collision> -->

        <inertial>
            <mass value="4.797"/>
            <inertia ixx="1.01100e+09" iyy="9.45199e+07" izz="9.47275e+08" ixy="-9.00000e-03" ixz="-8.00000e-03" iyz="2.36858e+08"/>
        </inertial>
    </link>

    <joint name="inner_column_joint" type="fixed">
        <axis xyz="0 0 1" />
        <limit velocity="0.01" effort="1000" lower="0" upper="0.0"/>
        <dynamics damping="0.7"/>
        <origin xyz="0.135 0 0.55" rpy="0 0 0"/>
        <parent link="base_column_link"/>
        <child link="inner_column_link"/>
    </joint>

    <link name="inner_column_link">
        <visual>
            <origin xyz="0 0 0.4" rpy="0 0 0"/>
            <geometry>
                <mesh
                    filename="package://humic_description/meshes/STL/column_inner.stl" scale="0.027 0.027 0.027"/>
            </geometry>
            <material name="white"/>
        </visual>

        <collision>
            <origin xyz="0 0 0.4" rpy="0 0 0"/>
            <geometry>
                <mesh
                    filename="package://humic_description/meshes/STL/column_inner.stl" scale="0.027 0.027 0.027"/>
            </geometry>
        </collision>        

        <inertial>
            <mass value="2.349"/>
            <inertia ixx="6.16980e+08" iyy="4.39384e+07" izz="5.85545e+08" ixy="7.48858e+05" ixz="1.26949e+05" iyz="1.35294e+08"/>
        </inertial>
    </link>

    <!-- Torso -->
    <joint name="torso_joint" type="fixed">
        <origin xyz="0 0 0" rpy="0 0 0"/> 
        <parent link="inner_column_link"/>
        <child link="torso_link"/>
    </joint>

    <link name="torso_link">
        <visual>
            <origin xyz="-0.0432 0 0.675" rpy="0 0 0"/>
            <geometry>
                <mesh
                    filename="package://humic_description/meshes/STL/torso.stl" scale="0.027 0.027 0.027"/>
            </geometry>
            <material name="white"/>
        </visual>

        <collision>
            <origin xyz="-0.0081 0 0.55" rpy="0 0 0"/>
            <geometry>
                <box size="0.297 0.432 0.405"/>
            </geometry>
        </collision>

        <!-- <collision>
            <origin xyz="-0.0432 0 0.675" rpy="0 0 0"/>
            <geometry>
                <mesh
                    filename="package://humic_description/meshes/STL/torso.stl" scale="0.027 0.027 0.027"/>
            </geometry>
        </collision> -->

        <inertial>
            <mass value="18.232"/>
            <inertia ixx="7.07404e+09" iyy="7.93876e+08" izz="6.78660e+09" ixy="-5.74440e+07" ixz="-1.45790e+07" iyz="1.56352e+09"/>
        </inertial>
    </link>

    <!-- head(Pan(neck), Tile(head), Kinect V2)-->
    <joint name="torso_neck_joint" type="fixed">
        <origin xyz="0 0 -0.0675" rpy="0 0 0"/>
        <parent link="torso_link"/>
        <child link="neck_link"/>
    </joint>

    <link name="neck_link">
        <visual>
            <origin xyz="-0.135 0 0" rpy="0 0 0"/>
            <geometry>
                <mesh
                    filename="package://humic_description/meshes/STL/neck.stl" scale="0.027 0.027 0.027"/>
            </geometry>
            <material name="white"/>
        </visual>

        <inertial>
            <mass value="0.732"/>
            <inertia ixx="4.90438e+08" iyy="2.52873e+07" izz="4.65475e+08" ixy="-4.24542e+03" ixz="-9.69919e+02" iyz="1.07698e+08"/>
        </inertial>
    </link>

    <joint name="neck_joint" type="fixed"> 
        <axis xyz="0 0 1" />
        <limit velocity="6.5" effort="1000" lower="-1.57" upper="1.57" />
        <dynamics damping="0.7"/>
        <origin xyz="0.0621 0 0.9099" rpy="0 0 0"/>
        <parent link="neck_link"/>
        <child link="head_link"/>
    </joint>

    <link name="head_link">
        <visual>
            <origin xyz="-0.1971 0 -0.9126" rpy="0 0 0"/>
            <geometry>
                <mesh
                    filename="package://humic_description/meshes/STL/neck_head.stl" scale="0.027 0.027 0.027"/>
            </geometry>
            <material name="white"/>
        </visual>

        <inertial>
            <mass value="0.087"/>
            <inertia ixx="6.80975e+07" iyy="3.08478e+06" izz="6.52339e+07" ixy="-2.97713e+05" ixz="-6.25864e+04" iyz="1.38758e+07"/>
        </inertial>
    </link>

    <joint name="head_joint" type="fixed">
        <axis xyz="0 -1 0" />
        <limit velocity="6.5" effort="1000" lower="-1.57" upper="1.57" />
        <dynamics damping="0.7"/>
        <origin xyz="0 0 0.05" rpy="0 0.7 0"/> 
        <parent link="head_link"/>
        <child link="head_kinect_link"/>
    </joint>

    <link name="head_kinect_link">
        <visual>
            <origin xyz="-0.2295 0 -0.945" rpy="0 0 0"/>
            <geometry>
                <mesh
                    filename="package://humic_description/meshes/STL/head_kinect.stl" scale="0.027 0.027 0.027"/>
            </geometry>
            <material name="white"/>
        </visual>

        <collision>
            <origin xyz="0 0 0.0648" rpy="0 0 0"/>
            <geometry>
                <box size="0.0945 0.2835 0.0864"/>
            </geometry>
        </collision>

        <inertial>
            <mass value="1.463"/>
            <inertia ixx="1.33775e+09" iyy="3.08478e+06" izz="1.27157e+09" ixy="1.06009e+06" ixz="2.26498e+05" iyz="1.38758e+07"/>
        </inertial>
    </link>

    <!-- Camera Sensor -->
    <joint name="camera_joint" type="fixed">
        <origin xyz="0 0 0" rpy="0 0 0"/>
        <parent link="head_kinect_link"/>
        <child link="camera_link"/>
    </joint>

    <link name="camera_link">
        <visual>
            <!-- <origin xyz="0.033 -0.0526 0.0675" rpy="0 0 0"/> -->
            <origin xyz="0.033 -0.1015 0.07" rpy="0 0 0"/>
            <geometry>
                <box size="0.001 0.001 0.001"/>
            </geometry>
            <material name="white"/>
        </visual>
    </link>

    <!-- Right ARM -->
    <joint name="r_arm_body_joint" type="fixed">
        <origin xyz="0 0 -0.0675" rpy="0 0 0"/>
        <parent link="torso_link"/>
        <child link="r_shoulder_link"/>
    </joint>

    <link name="r_shoulder_link">
        <visual>
            <origin xyz="-0.134 0.001 0.003" rpy="0 0 0"/>
            <geometry>
                <mesh
                    filename="package://humic_description/meshes/STL/r_shoulder.stl" scale="0.027 0.027 0.027"/>
            </geometry>
            <material name="white"/>
        </visual>

        <collision>
            <origin xyz="-0.134 0.001 0.003" rpy="0 0 0"/>
            <geometry>
                <mesh
                    filename="package://humic_description/meshes/STL/r_shoulder.stl" scale="0.027 0.027 0.027"/>
            </geometry>
        </collision>

        <inertial>
            <mass value="0.324"/>
            <inertia ixx="1.58637e+08" iyy="2.64707e+07" izz="1.72867e+08" ixy="-5.51744e+07" ixz="-1.09893e+07" iyz="3.03653e+07"/>
        </inertial>
    </link>

    <joint name="r_shoulder_joint" type="revolute">
        <axis xyz="0 -1 0" />
        <limit velocity="6.5" effort="1000" lower="-1.57" upper="1.57" />
        <dynamics damping="0.7"/>
        <origin xyz="0.0108 -0.3321 0.729" rpy="0 0 0"/>
        <parent link="r_shoulder_link"/>
        <child link="r_upperArm_link"/>
    </joint>

    <link name="r_upperArm_link">
        <visual>
            <origin xyz="-0.1458 0.3375 -0.7317" rpy="0 0 0"/>
            <geometry>
                <mesh
                    filename="package://humic_description/meshes/STL/r_upperArm.stl" scale="0.027 0.027 0.027"/>
            </geometry>
            <material name="white"/>
        </visual>

        <collision>
            <origin xyz="-0.1458 0.3375 -0.7317" rpy="0 0 0"/>
            <geometry>
                <mesh
                    filename="package://humic_description/meshes/STL/r_upperArm.stl" scale="0.027 0.027 0.027"/>
            </geometry>
        </collision>

        <inertial>
            <mass value="0.353"/>
            <inertia ixx="1.73491e+08" iyy="4.90592e+07" izz="2.08142e+08" ixy="-8.33193e+07" ixz="-1.67769e+07" iyz="3.34583e+07"/>
        </inertial>
    </link>

    <joint name="r_upperArm_joint" type="revolute">
        <axis xyz="1 0 0" />
        <limit velocity="6.5" effort="1000" lower="-1.57" upper="1.57" />
        <dynamics damping="0.7"/>
        <origin xyz="0 -0.0297 0" rpy="-1.57 0 0"/>
        <parent link="r_upperArm_link"/>
        <child link="r_elbow_link"/>
    </joint>

    <link name="r_elbow_link">
        <visual>
            <origin xyz="-0.1458 0.3672 -0.7317" rpy="0 0 0"/>
            <geometry>
                <mesh
                    filename="package://humic_description/meshes/STL/r_elbow.stl" scale="0.027 0.027 0.027"/>
            </geometry>
            <material name="white"/>
        </visual>

        <collision>
            <origin xyz="-0.1458 0.3672 -0.7317" rpy="0 0 0"/>
            <geometry>
                <mesh
                    filename="package://humic_description/meshes/STL/r_elbow.stl" scale="0.027 0.027 0.027"/>
            </geometry>
        </collision>

        <inertial>
            <mass value="0.529"/>
            <inertia ixx="1.38870e+08" iyy="6.80593e+07" izz="1.85969e+08" ixy="-8.50240e+07" ixz="-2.38516e+07" iyz="3.52215e+07"/>
        </inertial>
    </link>

    <joint name="r_elbow_joint" type="revolute">
        <axis xyz="1 0 0" />
        <limit velocity="6.5" effort="1000" lower="-0.785" upper="0.785" />
        <dynamics damping="0.7"/>
        <origin xyz="0 0.0297 -0.2835" rpy="1.57 0 0"/>
        <parent link="r_elbow_link"/>
        <child link="r_foreArm_link"/>
    </joint>

    <link name="r_foreArm_link">
        <visual>
            <origin xyz="-0.1458 0.3375 -0.4482" rpy="0 0 0"/>
            <geometry>
                <mesh
                    filename="package://humic_description/meshes/STL/r_foreArm.stl" scale="0.027 0.027 0.027"/>
            </geometry>
            <material name="white"/>
        </visual>

        <collision>
            <origin xyz="-0.1458 0.3375 -0.4482" rpy="0 0 0"/>
            <geometry>
                <mesh
                    filename="package://humic_description/meshes/STL/r_foreArm.stl" scale="0.027 0.027 0.027"/>
            </geometry>
        </collision>

        <inertial>
            <mass value="0.501"/>
            <inertia ixx="5.38306e+07" iyy="6.94958e+07" izz="1.03905e+08" ixy="-5.05255e+07" ixz="-2.36971e+07" iyz="2.00992e+07"/>
        </inertial>
    </link>

    <joint name="r_foreArm_joint" type="revolute">
        <axis xyz="0 0 -1" />
        <limit velocity="6.5" effort="1000" lower="-1.57" upper="1.57"/>
        <dynamics damping="0.7"/>
        <origin xyz="0 -0.0297 -0.243" rpy="0 0 0"/>
        <parent link="r_foreArm_link"/>
        <child link="r_lowerArm_link"/>
    </joint>

    <link name="r_lowerArm_link">
        <visual>
            <origin xyz="-0.1458 0.3672 -0.2052" rpy="0 0 0"/>
            <geometry>
                <mesh
                    filename="package://humic_description/meshes/STL/r_lowerArm.stl" scale="0.027 0.027 0.027"/>
            </geometry>
            <material name="white"/>
        </visual>

        <collision>
            <origin xyz="-0.1458 0.3672 -0.2052" rpy="0 0 0"/>
            <geometry>
                <mesh
                    filename="package://humic_description/meshes/STL/r_lowerArm.stl" scale="0.027 0.027 0.027"/>
            </geometry>
        </collision>

        <inertial>
            <mass value="0.144"/>
            <inertia ixx="6.68413e+06" iyy="1.98639e+07" izz="2.10626e+07" ixy="-8.18631e+06" ixz="-6.74644e+06" iyz="3.22949e+06"/>
        </inertial>
    </link>

    <joint name="r_lowerArm_joint" type="revolute">
        <axis xyz="1 0 0" />
        <limit velocity="6.5" effort="1000" lower="-1.57" upper="1.57" />
        <dynamics damping="0.7"/>
        <origin xyz="0 0 -0.0324" rpy="0 0 0"/>
        <parent link="r_lowerArm_link"/>
        <child link="r_wrist_link"/>
    </joint>

    <link name="r_wrist_link">
        <visual>
            <origin xyz="-0.1458 0.3672 -0.1728" rpy="0 0 0"/>
            <geometry>
                <mesh
                    filename="package://humic_description/meshes/STL/r_wrist.stl" scale="0.027 0.027 0.027"/>
            </geometry>
            <material name="white"/>
        </visual>

        <collision>
            <origin xyz="-0.1458 0.3672 -0.1728" rpy="0 0 0"/>
            <geometry>
                <mesh
                    filename="package://humic_description/meshes/STL/r_wrist.stl" scale="0.027 0.027 0.027"/>
            </geometry>
        </collision>

        <inertial>
            <mass value="0.163"/>
            <inertia ixx="4.76597e+06" iyy="2.26942e+07" izz="2.11061e+07" ixy="-5.33281e+06" ixz="-7.80384e+06" iyz="2.14027e+06"/>
        </inertial>
    </link>

    <joint name="r_wrist_joint" type="revolute">
        <axis xyz="0 0 -1" />
        <limit velocity="6.5" effort="1000" lower="-1.57" upper="1.57" />
        <dynamics damping="0.7"/>
        <origin xyz="0 0 -0.1756" rpy="0 0 0"/>
        <parent link="r_wrist_link"/>
        <child link="r_hand_link"/>
    </joint>
    
    <link name="r_hand_link">
        <visual>
            <origin xyz="-0.03 0.002 0.0465" rpy="-3.14 0 0"/>
            <geometry>
                <mesh
                    filename="package://humic_description/meshes/STL/HUMIC_HAND_70mm.stl" scale="0.001 0.001 0.001"/>
            </geometry>
            <material name="white"/>
        </visual>

        <collision>
            <origin xyz="-0.03 0.002 0.0465" rpy="-3.14 0 0"/>
            <geometry>
                <mesh
                    filename="package://humic_description/meshes/STL/HUMIC_HAND_70mm.stl" scale="0.001 0.001 0.001"/>
            </geometry>
        </collision>

        <inertial>
            <mass value="0.072"/>
            <inertia ixx="1.38325e+06" iyy="9.65946e+06" izz="8.41135e+06" ixy="7.83401e+04" ixz="-3.27407e+06" iyz="-2.39035e+04"/>
        </inertial>
    </link>

    <!-- Left ARM -->
    <joint name="l_arm_body_joint" type="fixed">
        <origin xyz="0 0 -0.0675" rpy="0 0 0"/>
        <parent link="torso_link"/>
        <child link="l_shoulder_link"/>
    </joint>

    <link name="l_shoulder_link">
        <visual>
            <origin xyz="-0.134 0.001 0.003" rpy="0 0 0"/>
            <geometry>
                <mesh
                    filename="package://humic_description/meshes/STL/l_shoulder.stl" scale="0.027 0.027 0.027"/>
            </geometry>
            <material name="white"/>
        </visual>

        <collision>
            <origin xyz="-0.134 0.001 0.003" rpy="0 0 0"/>
            <geometry>
                <mesh
                    filename="package://humic_description/meshes/STL/l_shoulder.stl" scale="0.027 0.027 0.027"/>
            </geometry>
        </collision>

        <inertial>
            <mass value="0.324"/>
            <inertia ixx="1.58637e+08" iyy="2.64707e+07" izz="1.72867e+08" ixy="5.51744e+07" ixz="1.09893e+07" iyz="3.03653e+07"/>
        </inertial>
    </link>

    <joint name="l_shoulder_joint" type="revolute"> 
        <axis xyz="0 1 0" />
        <limit velocity="6.5" effort="1000" lower="-1.57" upper="1.57" />
        <dynamics damping="0.7"/>
        <origin xyz="0.0108 0.3321 0.729" rpy="0 0 0"/>
        <parent link="l_shoulder_link"/>
        <child link="l_upperArm_link"/>
    </joint>

    <link name="l_upperArm_link">
        <visual>
            <origin xyz="-0.1458 -0.3375 -0.7317" rpy="0 0 0"/>
            <geometry>
                <mesh
                    filename="package://humic_description/meshes/STL/l_upperArm.stl" scale="0.027 0.027 0.027"/>
            </geometry>
            <material name="white"/>
        </visual>

        <collision>
            <origin xyz="-0.1458 -0.3375 -0.7317" rpy="0 0 0"/>
            <geometry>
                <mesh
                    filename="package://humic_description/meshes/STL/l_upperArm.stl" scale="0.027 0.027 0.027"/>
            </geometry>
        </collision>

        <inertial>
            <mass value="0.353"/>
            <inertia ixx="1.73201e+08" iyy="4.87701e+07" izz="2.08141e+08" ixy="8.33190e+07" ixz="1.64043e+07" iyz="3.27317e+07"/>
        </inertial>
    </link>

    <joint name="l_upperArm_joint" type="revolute"> 
        <axis xyz="-1 0 0" />
        <limit velocity="6.5" effort="1000" lower="-1.57" upper="1.57" />
        <dynamics damping="0.7"/>
        <origin xyz="0 0.0297 0" rpy="1.57 0 0"/>
        <parent link="l_upperArm_link"/>
        <child link="l_elbow_link"/>
    </joint>


    <link name="l_elbow_link">
        <visual>
            <origin xyz="-0.1458 -0.3672 -0.7317" rpy="0 0 0"/>
            <geometry>
                <mesh
                    filename="package://humic_description/meshes/STL/l_elbow.stl" scale="0.027 0.027 0.027"/>
            </geometry>
            <material name="white"/>
        </visual>

        <collision>
            <origin xyz="-0.1458 -0.3672 -0.7317" rpy="0 0 0"/>
            <geometry>
                <mesh
                    filename="package://humic_description/meshes/STL/l_elbow.stl" scale="0.027 0.027 0.027"/>
            </geometry>
        </collision>

        <inertial>
            <mass value="0.529"/>
            <inertia ixx="1.38809e+08" iyy="6.79988e+07" izz="1.85969e+08" ixy="8.50239e+07" ixz="2.37845e+07" iyz="3.50234e+07"/>
        </inertial>
    </link>

    <joint name="l_elbow_joint" type="revolute"> 
        <axis xyz="-1 0 0" />
        <limit velocity="6.5" effort="1000" lower="-0.785" upper="0.785" />
        <dynamics damping="0.7"/>
        <origin xyz="0 -0.0297 -0.2835" rpy="-1.57 0 0"/>
        <parent link="l_elbow_link"/>
        <child link="l_foreArm_link"/>
    </joint>

    <link name="l_foreArm_link">
        <visual>
            <origin xyz="-0.1458 -0.3375 -0.4482" rpy="0 0 0"/>
            <geometry>
                <mesh
                    filename="package://humic_description/meshes/STL/l_foreArm.stl" scale="0.027 0.027 0.027"/>
            </geometry>
            <material name="white"/>
        </visual>

        <collision>
            <origin xyz="-0.1458 -0.3375 -0.4482" rpy="0 0 0"/>
            <geometry>
                <mesh
                    filename="package://humic_description/meshes/STL/l_foreArm.stl" scale="0.027 0.027 0.027"/>
            </geometry>
        </collision>

        <inertial>
            <mass value="0.501"/>
            <inertia ixx="5.37910e+07" iyy="6.94563e+07" izz="1.03905e+08" ixy="5.05255e+07" ixz="2.36541e+07" iyz="2.00295e+07"/>
        </inertial>
    </link>

    <joint name="l_foreArm_joint" type="revolute"> 
        <axis xyz="0 0 -1" />
        <limit velocity="6.5" effort="1000" lower="-1.57" upper="1.57" />
        <dynamics damping="0.7"/>
        <origin xyz="0 0.0297 -0.243" rpy="0 0 0"/>
        <parent link="l_foreArm_link"/>
        <child link="l_lowerArm_link"/>
    </joint>

    <link name="l_lowerArm_link">
        <visual>
            <origin xyz="-0.1458 -0.3672 -0.2052" rpy="0 0 0"/>
            <geometry>
                <mesh
                    filename="package://humic_description/meshes/STL/l_lowerArm.stl" scale="0.027 0.027 0.027"/>
            </geometry>
            <material name="white"/>
        </visual>

        <collision>
            <origin xyz="-0.1458 -0.3672 -0.2052" rpy="0 0 0"/>
            <geometry>
                <mesh
                    filename="package://humic_description/meshes/STL/l_lowerArm.stl" scale="0.027 0.027 0.027"/>
            </geometry>
        </collision>

        <inertial>
            <mass value="0.144"/>
            <inertia ixx="6.75832e+06" iyy="1.99380e+07" izz="2.10627e+07" ixy="8.18639e+06" ixz="6.83971e+06" iyz="3.27467e+06"/>
        </inertial>
    </link>

    <joint name="l_lowerArm_joint" type="revolute"> 
        <axis xyz="-1 0 0" />
        <limit velocity="6.5" effort="1000" lower="-1.57" upper="1.57" />
        <dynamics damping="0.7"/>
        <origin xyz="0 0 -0.0324" rpy="0 0 0"/>
        <parent link="l_lowerArm_link"/>
        <child link="l_wrist_link"/>
    </joint>

    <link name="l_wrist_link">
        <visual>
            <origin xyz="-0.1458 -0.3672 -0.1728" rpy="0 0 0"/>
            <geometry>
                <mesh
                    filename="package://humic_description/meshes/STL/l_wrist.stl" scale="0.027 0.027 0.027"/>
            </geometry>
            <material name="white"/>
        </visual>

        <collision>
            <origin xyz="-0.1458 -0.3672 -0.1728" rpy="0 0 0"/>
            <geometry>
                <mesh
                    filename="package://humic_description/meshes/STL/l_wrist.stl" scale="0.027 0.027 0.027"/>
            </geometry>
        </collision>

        <inertial>
            <mass value="0.163"/>
            <inertia ixx="4.65423e+06" iyy="2.25825e+07" izz="2.11060e+07" ixy="5.33269e+06" ixz="7.66325e+06" iyz="2.09064e+06"/>
        </inertial>
    </link>

    <joint name="l_wrist_joint" type="revolute"> 
        <axis xyz="0 0 -1" />
        <limit velocity="6.5" effort="1000" lower="-1.57" upper="1.57" />
        <dynamics damping="0.7"/>
        <origin xyz="0 0 -0.1756" rpy="0 0 0"/>
        <parent link="l_wrist_link"/>
        <child link="l_hand_link"/>
    </joint>

    <link name="l_hand_link">
        <visual>
            <origin xyz="-0.03 0.002 0.0465" rpy="-3.14 0 0"/>
            <geometry>
                <mesh
                    filename="package://humic_description/meshes/STL/HUMIC_HAND_70mm.stl" scale="0.001 0.001 0.001"/>
            </geometry>
            <material name="white"/>
        </visual>

        <collision>
            <origin xyz="-0.03 0.002 0.0465" rpy="-3.14 0 0"/>
            <geometry>
                <mesh
                    filename="package://humic_description/meshes/STL/HUMIC_HAND_70mm.stl" scale="0.001 0.001 0.001"/>
            </geometry>
        </collision>


        <inertial>
            <mass value="0.072"/>
            <inertia ixx="1.36468e+06" iyy="9.64090e+06" izz="8.41131e+06" ixy="-7.81787e+04" ixz="3.25059e+06" iyz="-2.37841e+04"/>
        </inertial>
    </link>

</robot>
